Workbook

Sheet Start here
A1: SLAM build spec
A2: Tab | B2: What it is | C2: Use it for
A3: Start here | B3: This page | C3: What each tab is and the order to read them
A4: Roadmap | B4: Phases 1 to 8 | C4: Where we are (phase 2) and what each later phase holds
A5: Feature list | B5: Every feature, tagged | C5: Core, Standard, Only SLAM, all 9 YMOYL steps, books/blogs/podcasts, next-level ideas; who each comes from, its time view and phase
A6: Visualizations | B6: Every chart | C6: What each chart looks like, what it reads, where it lives, and its time view
A7: Build phases | B7: How phase 3 gets built | C7: 12 build steps in dependency order, each with 'done when'
A8: QA checklist | B8: How you'll check each phase | C8: What you click and what you should see before saying 'next'
A9: Look and feel | B9: Colors, type, spacing, formats | C9: Exact values so nothing is left to taste. Proposed values marked
A10: Words and states | B10: Tone, empty states, errors | C10: What each screen says before anything is entered, and every confirmation
A11: Navigation | B11: Where everything lives | C11: Site map, one home for every thing, click paths for common tasks
A12: DMMT check | B12: Don't Make Me Think audit | C12: Each Krug principle, how it's applied, what was fixed, what to watch
A13: Screens | B13: The 8 screens | C13: Purpose, when used, who sees it
... A25: Open questions | B25: Still to decide | C25: Answer in the yellow column

Sheet Roadmap
A1: Roadmap: we're in phase 2
A2: Phase | B2: Name | C2: Status | D2: What's in it | E2: Done means
A3: 1 | B3: Experiments | C3: Done | D3: Money Rooms v1 to v3, SPARKS, SLAM in Personalfinance | E3: Learned what works; left baggage
A4: 2 | B4: The spec | C4: Now | D4: This workbook: every field, rule, formula, screen and feature | E4: One source of truth, nothing built from old code
A5: 3 | B5: Rebuild the core | C5: Next | D5: Build phases 0 to 11: records, math, staples, navigation, My Money, Spending, Plan, Report, Home, coach tools, dry run. All Core, Standard and 'Now' items | E5: Ready to run a live session 1 with a client
A6: 4 | B6: Coaching depth | C6: Later | D6: YMOYL exercises, joy per dollar, What Matters, mistake tracker, graceful degradation, small wins, Pareto, statement upload (CSV and PDF), canon checks (Baby Steps, Conscious Spending, PAW/UAW) | E6: Every monthly money date has something new to look at
A7: 5 | B7: The future, in depth | C7: Later | D7: True FI, decumulation, Roth ladder, 72(t), rule of 55, ACA, Social Security, life simulator, scenarios, Die With Zero, geo arbitrage, house hack, side income tools | E7: One plan from now through retirement
A8: 6 | B8: Clients in the app | C8: Later | D8: Phone-first client view, client logging between sessions, comments, pre-call link, monthly money date, next-level features | E8: Clients use it between sessions
A9: 7 | B9: Delight and community | C9: Later | D9: Wrapped, advice translator, shareable milestones, peer comparison, community money date | E9: People share it
A10: 8 | B10: Connect | C10: Someday | D10: Bank connection, paystub and 1040 readers | E10: Less typing

Sheet Feature list
A1: Every feature, tagged by tier, person, source and phase
A2: Tier | B2: Feature | C2: What it does | D2: Inspired by (people) | E2: Source | F2: Time view | G2: Phase | H2: In spec? | I2: Your comments
A3: CORE: a budgeting app built from scratch
A4: Core | B4: Records for every money item | C4: One record type behind bills, paychecks, debts, accounts | E4: Every budgeting app | F4: Every record can show its hours | G4: 3 | H4: Yes
A5: Core | B5: Budget with five passes | C5: Gut, Basics, Rough, Estimate, Actual | D5: Eli | E5: SLAM | F5: Each line in hours of work | G5: 3 | H5: Yes
A6: Core | B6: Cash flow calendar | C6: Day-by-day in and out with a running balance | E6: Every budgeting app | F6: Hours worked to cover each bill | G6: 3 | H6: Yes
A7: Core | B7: Net worth, liquid and total | C7: Assets minus debts, two ways | E7: Every planning app | F7: Net worth as months of freedom | G7: 3 | H7: Yes
A8: Core | B8: Debt payoff dates and interest | C8: Months, date, total interest per debt | E8: Every debt app | F8: Interest as hours of work | G8: 3 | H8: Yes
A9: Core | B9: Savings rate | C9: Take-home headline, gross in Show the math | D9: Mr. Money Mustache | E9: MMM blog | F9: Days of freedom bought per month | G9: 3 | H9: Yes
A10: Core | B10: Month-end close | C10: Actuals vs estimates, misses, carry adjustments | E10: YNAB-style apps | G10: 3 | H10: Yes
A11: Core | B11: Export, import, undo, autosave | C11: Never lose work | G11: 3 | H11: Yes
A12: STANDARD: what the well-known apps have
A13: Standard | B13: FI number and FI date | C13: Spending / withdrawal rate, then a monthly projection | D13: Trinity Study authors; Mindy Jensen, Scott Trench | E13: Trinity Study; BiggerPockets Money | F13: Countdown in months | G13: 3 | H13: Yes
A14: Standard | B14: FI milestones (Lean, Coast, Barista, Regular, Fat) | C14: Dated or condition-based milestones | D14: FIRE community | E14: r/financialindependence, ProjectionLab | F14: Months to each | G14: 3 | H14: Yes
A15: Standard | B15: Avalanche and snowball payoff | C15: Order and simulated payoff with extra payments | D15: Dave Ramsey (snowball) | E15: The Total Money Makeover | F15: Months saved | G15: 3 | H15: Yes
A16: Standard | B16: Cash flow Sankey | C16: Income to spending to saving | E16: ProjectionLab, Monarch | F16: Hours per branch | G16: 3 | H16: Yes
A17: Standard | B17: Category charts | C17: Where the money went | E17: YNAB, Monarch, Rocket Money | F17: Hours per category | G17: 3 | H17: Yes
A18: Standard | B18: Recurring bills list | C18: Every repeating charge and date | E18: Rocket Money | F18: Hours per year per subscription | G18: 3 | H18: Yes
A19: Standard | B19: Couples in one household | C19: Owner on every row, joint | E19: Monarch | G19: 3 | H19: Yes
A20: Standard | B20: Tax estimate | C20: Federal plus FICA | E20: Boldin | F20: Hours worked for taxes | G20: 3 | H20: Yes
A21: Standard | B21: Contribution limit tracking | C21: How much of each limit is used | E21: Boldin, Empower | G21: 3 | H21: Yes
A22: Standard | B22: Give every dollar a job | C22: Zero-based plan: income minus planned = $0 | D22: Jesse Mecham | E22: YNAB | G22: 4 | H22: Backlog
A23: Standard | B23: Sinking funds | C23: Save monthly for known yearly costs | E23: YNAB, budgeting community | F23: Hours per month set aside | G23: 3 | H23: Yes (irregular costs)
A24: Standard | B24: Statement upload (CSV and PDF) | C24: Lines matched to records, duplicates flagged | E24: Most apps | G24: 4 | H24: Backlog
A25: ONLY SLAM: ideas nobody else has
A26: Only SLAM | B26: These are big deals | C26: FI date under every return, inflation and withdrawal preset; names the biggest mover | D26: Eli | E26: SLAM | F26: Years of work each assumption adds | G26: 3 | H26: Yes
A27: Only SLAM | B27: Money as time, everywhere | C27: One toggle: dollars, hours of work, or FI days, on every number | D27: Vicki Robin, Joe Dominguez; Grant Sabatier | E27: Your Money or Your Life; Financial Freedom | F27: This is the time view | G27: 3 | H27: Yes
A28: Only SLAM | B28: Stress-weighted payoff | C28: Order debts by how much they weigh on you, with the extra interest shown | D28: Eli | E28: SLAM | F28: Hours of extra work for peace of mind | G28: 3 | H28: Yes
A29: Only SLAM | B29: Gut accuracy score | C29: How far the client's own guesses were from actual, over time | D29: Eli | E29: SLAM | G29: 3 | H29: Yes
A30: Only SLAM | B30: Amount and timing grid | C30: Fixed/variable amount x fixed/variable date; different move for each | D30: Eli | E30: SLAM | G30: 3 | H30: Yes
A31: Only SLAM | B31: Rule of 5 | C31: Age / 5 months of savings with the exact monthly add | D31: Eli | E31: SLAM | F31: Months of freedom held | G31: 3 | H31: Yes
A32: Only SLAM | B32: Support received | C32: How much others cover and what happens if it stops | D32: Eli | E32: SLAM | F32: Hours others work for you | G32: 3 | H32: Yes
A33: Only SLAM | B33: Maybe money | C33: Expected income kept out of the balance until it lands | D33: Eli; Lindsey Swanson, Jessica Goedtel (irregular income planning) | E33: Sex-worker financial planning | G33: 3 | H33: Yes
A34: Only SLAM | B34: Wins on the calendar | C34: Payoffs, milestones, raises as dated chips | D34: Eli | E34: SLAM | G34: 3 | H34: Yes
A35: Only SLAM | B35: Show the math | C35: Click any computed number to see its formula filled in with the client's numbers | D35: Eli | E35: SLAM | G35: 3 | H35: Yes
A36: Only SLAM | B36: Change since last session | C36: ▲ ▼ differences under key numbers | D36: Eli | E36: SLAM | G36: 3 | H36: Yes
A37: Only SLAM | B37: Live-call keyboard flow | C37: Tab, Enter for a new row, / for Find, Ctrl+Z | D37: Eli | E37: SLAM | G37: 3 | H37: Yes
A38: Only SLAM | B38: Benefit finder | C38: Unused employer benefits and their value | D38: Eli | E38: SLAM | F38: Hours of pay left on the table | G38: 3 | H38: Yes
A39: Only SLAM | B39: Materiality by your hourly wage | C39: Hides anything worth less than your time | D39: Eli (audit thinking) | E39: SLAM | F39: Built on the time view | G39: 3 | H39: Yes
A40: Only SLAM | B40: Solvers | C40: What would have to be true to hit FI by an age; payment to beat a promo | D40: Eli | E40: SLAM | G40: 3 | H40: Yes
...

Sheet Visualizations
A1: Every chart and what it looks like
A2: Chart | B2: Type | C2: What you see | D2: Reads | E2: Where it lives | F2: Interaction | G2: Time view
A3: Net worth donuts | B3: Rings | C3: Big ring for net worth split by account type; smaller rings for assets, liabilities, equity; tabs underneath open each list | D3: Accounts, debts | E3: Report > Overview | F3: Hover shows the item; click jumps to its home | G3: Months of freedom in the center
A4: Net worth over time | B4: Line | C4: One line per snapshot date; dots where sessions happened; dashed line for liquid net worth | D4: Snapshots, history | E4: Report > History | F4: Drag to zoom a range | G4: Months of freedom on the second axis
A5: Cash flow Sankey | B5: Sankey | C5: Income on the left flows into taxes, needs, wants, debt, saving on the right; width = dollars | D5: Income, spending lines | E5: Report > Overview | F5: Click a branch to filter the budget | G5: Branch width in hours
A6: Gross to take-home | B6: Waterfall | C6: Gross bar steps down through federal, FICA, pretax deductions to take-home | D6: Income, Math M10-M12 | E6: My Money > Income | F6: Hover shows each amount | G6: Hours of each workday spent on each
A7: DRAFTT shares | B7: 100% bar | C7: One horizontal bar split into Debt, Retirement, Accommodation, Food, Transportation, (Taxes, Therapy) | D7: Spending lines | E7: My Money visuals panel, Report | F7: Click a letter to see its lines | G7: Hours per letter
A8: Amount and timing grid | B8: 2x2 bubbles | C8: Four boxes (fixed/variable amount x fixed/variable date); bubble size = dollars; bottom-right box shaded as risk | D8: Spending lines | E8: Spending > Budget | F8: Click a box to filter | G8: Bubble labels in hours
A9: Estimate vs actual | B9: Bullet bars | C9: Per line: grey estimate bar, solid actual bar, a tick for Gut | D9: Budget passes | E9: Spending > Month-end close | F9: Sort by biggest miss | G9: Misses in hours
A10: Gut accuracy over time | B10: Line | C10: Average % off per month falling over time | D10: History | E10: Report > History
A11: Running balance | B11: Line under the calendar | C11: Thin line of end-of-day balance with the low balance line dashed; maybe money as a dotted band | D11: Calendar entries | E11: Spending > Cash flow calendar | F11: Hover a day | G11: Days of runway
A12: Debt payoff | B12: Stacked area | C12: Each debt's balance shrinking to zero; flags at each payoff date | D12: Debts, Math M34 | E12: Plan > Debt payoff | F12: Extra payment slider moves the flags | G12: Interest in hours
A13: Payoff order compare | B13: Grouped bars | C13: Avalanche vs snowball vs stress: months and total interest side by side | D13: Math M34 | E13: Plan > Debt payoff | G13: Hours of interest
A14: FI timeline | B14: Line with fan | C14: Invested balance rising to the FI line; pessimistic to optimistic band; milestone flags | D14: Math M53 | E14: Plan > Timeline | F14: Savings slider moves the date | G14: Years of work left
A15: These are big deals | B15: Tornado | C15: One bar per assumption showing how far it moves the FI date; biggest on top | D15: Math M56 | E15: Plan > Goals | F15: Click a bar to set that preset | G15: Years per assumption
A16: Milestone ladder | B16: Steps | C16: Lean, Coast, Barista, Regular, Fat FI as stairs, each filled by % | D16: Math M55 | E16: Plan > Goals | G16: Months to each step
A17: Savings rate to years | B17: Curve | C17: MMM's curve of savings rate vs years to FI with your dot on it | D17: Math | E17: Plan > Timeline | F17: Drag your dot | G17: This is in years
A18: Crossover point | B18: Two lines | C18: Monthly investment income rising to meet monthly spending (YMOYL wall chart) | D18: Math | E18: Plan > Timeline
A19: Fulfillment curve | B19: Curve | C19: Survival, comforts, luxuries, enough; each category placed on it | D19: Three questions | E19: Spending (phase 4)
A20: Rule of 5 gauge | B20: Gauge | C20: Emergency cash vs age/5 months target; keep-pace add shown under it | D20: Math M43 | E20: My Money > Assets, Home | G20: Months held
A21: Graceful degradation | B21: Staircase | C21: Months at full spending, DRAFTT, FAT, food and housing only | D21: Math | E21: Report (phase 4) | G21: Months at each step
A22: Joy per dollar | B22: Scatter | C22: Cost on x, happiness on y; top-left = cheap joy, bottom-right = expensive and joyless | D22: Happiness ratings | E22: Spending (phase 4) | F22: Click a dot to open the line | G22: Cost in hours
A23: Pareto | B23: Bars plus line | C23: Biggest spends as bars with the cumulative % line | D23: Calendar actuals | E23: Report (phase 4) | G23: Hours per spend
A24: Life Pyramid | B24: Pyramid bars | C24: Maslow levels as bars showing spending at each | D24: Spending lines | E24: Report (phase 4)
A25: Support received | B25: Stacked bar | C25: Your share vs others' share for each covered line | D25: Who pays | E25: Report > Overview | G25: Hours others cover
A26: Contribution limits | B26: Progress bars | C26: Each account's year-to-date vs its limit | D26: Reference data | E26: My Money > Assets
A27: Expected net worth | B27: Gauge | C27: Actual net worth vs age x income / 10 | D27: PAW/UAW formula | E27: Report (phase 4)
A28: Money as time chips | B28: Inline chips | C28: Small grey chip next to any amount: '14 hrs' or '3 FI days' | D28: Real hourly wage | E28: Everywhere | F28: Global toggle | G28: This is the time view
A29: Wrapped | B29: Story cards | C29: Swipeable cards: biggest win, debt paid, accuracy, top categories, hours saved | D29: History | E29: Report (phase 7) | G29: Hours saved this year

Sheet Build phases
A1: Build phases, in dependency order
A2: Phase | B2: Name | C2: What gets built | D2: Done when
A3: 0 | B3: Setup | C3: New repo, /spec from this workbook (one CSV per tab), test runner, .gitignore for fixtures/*.local.json | D3: Repo runs locally; spec files exist; Test client is NOT in git
A4: 1 | B4: Records and storage | C4: One record type, dated history on every change, autosave, undo/redo, snapshots, export/import | D4: Unit tests: add, edit, delete, undo, history, export → import round-trips
A5: 2 | B5: Math engine | C5: Every Math tab formula as a pure function with tests | D5: All Test client expected values match within $1 or 1 month
A6: 3 | B6: Staples | C6: All Staples tab pieces on one demo page | D6: Each staple works on the demo page; affordances pass (buttons look like buttons)
A7: 4 | B7: Shell and navigation | C7: Top bar (left, middle, right), 5 tabs, sub-tabs, breadcrumb, Find, quick add, parking lot, client view, gear | D7: Trunk test passes on every empty screen
A8: 5 | B8: My Money | C8: Profile with gates hub, Income, Debt, Assets, Protection, Taxes; Fast Track mode; One page toggle; visuals panel | D8: Your test client can be entered start to finish; gates add and remove sections
A9: 6 | B9: Spending | C9: Budget with five passes, fixed/variable and timing tags, who pays, bulk select, link to card, irregular costs; calendar; month-end close | D9: A full month can be planned, logged and closed for the test client
A10: 7 | B10: Plan | C10: Goals with presets, big-deals card, milestones, timeline, debt payoff, next 12 months, solvers | D10: FI dates match the Test client expected values
A11: 8 | B11: Report | C11: Overview (donuts, metrics shelf, Sankey), one-pager, history | D11: Every number links to its home
A12: 9 | B12: Home | C12: Prep, Live, Wrap-up with one main button each | D12: A mock session runs from Start session to Send summary
A13: 10 | B13: Coach tools and discovery | C13: Revisit list, homework, snapshots, export, reset, notes, discovery table, new client | D13: New client from discovery opens Home in Prep
A14: 11 | B14: Dry run | C14: Full fake session 1 end to end; screenshots; QUESTIONS.md | D14: You do one real run-through and log every 'where do I put this'

Sheet QA checklist
A1: How you'll check each phase
A2: Build phase | B2: Name | C2: What you do | D2: What you should see
A3: 0 | B3: Setup | C3: Open the repo on GitHub | D3: spec/csv has one file per tab; .gitignore lists fixtures/*.local.json; no real numbers anywhere
A4: 1 | B4: Records | C4: Run the tests (Claude Code reports them); open the staples page later | D4: Add, edit, delete, undo, history and export/import tests pass
A5: 2 | B5: Math | C5: Read the report's match table | D5: Every Demo client and Test client expected value matches within $1 or 1 month
A6: 3 | B6: Staples | C6: Open the staples demo page | D6: Every staple from the Staples tab is there; it looks like the approved preview page; every box in a row lines up; time toggle changes amounts
A7: 4 | B7: Shell | C7: Click every tab and sub-tab; drop yourself on a random screen | D7: Trunk test: site, client, page, sections, search all visible; nothing says $0; empty states read like the Words tab
A8: 5 | B8: My Money | C8: Enter your own numbers with Fast Track, then in full | D8: Under 5 minutes for Fast Track; gates add and remove sections; car loan shows on Assets and Debt
A9: 6 | B9: Spending | C9: Plan, log and close one month | D9: Calendar balance matches the budget; Partial and Maybe behave; bulk select links bills to a card in 3 clicks
A10: 7 | B10: Plan | C10: Change presets on the big-deals card | D10: FI date matches the expected values; tornado names the biggest mover
A11: 8 | B11: Report | C11: Click every number | D11: Each number opens its home
A12: 9 | B12: Home | C12: Run Start session to Send summary | D12: One main button per moment; wrap-up does all four steps
A13: 10 | B13: Coach tools | C13: Create a client from discovery | D13: Opens Home in Prep with the discovery numbers marked Roughly
A14: 11 | B14: Dry run | C14: A full fake session 1 | D14: Your 'where do I put this' list is empty, or becomes the next prompt

Sheet Look and feel
A1: Look and feel (proposed values marked)
A2: Item | B2: Value | C2: Used for | D2: Status
A3: COLORS (from the preview, Oct 28, version 3)
A4: Modes | B4: Light and dark, both designed. Follows the computer's setting, with a Light | Dark switch in settings | D4: Decided (your feedback)
A5: Page background | B5: Light: #E4E9F2 soft blue-grey (not bright white). Dark: #0E1729 | D5: Decided (your feedback)
A6: Cards and rows | B6: Light: #F2F5FA. Dark: #16223D | D6: Decided
A7: Text | B7: Light: #060E1F, weight 500. Dark: #F4F7FC | C7: High contrast | D7: Decided (your feedback)
A8: Secondary text | B8: Light: #26344F. Dark: #CBD6EA | D8: Decided
A9: Primary (sapphire) | B9: Light: #1747A6. Dark: #7AA6F5 with dark text on it | C9: Main buttons, current tab and sub-tab | D9: Decided
A10: Primary dark | B10: Light: #0A2A66. Dark: #06142F | C10: Top bar, warnings | D10: Decided
A11: Primary light | B11: Light: #9FB9EA. Dark: #2C4A85 | C11: Selected rows (deeper than before) | D11: Decided (your feedback)
A12: Computed fill | B12: Light: #CBD6EA. Dark: #24365C | C12: Can't be typed in; text stays dark/light | D12: Decided
A13: Borders | B13: Light: #4E6694 on inputs and buttons, #A9B9D6 row lines. Dark: #8AA2CF and #344A75 | D13: Decided
A14: Small icon buttons | B14: 32px, 2px dark outline, bold 17px icon. Top bar: solid white with navy icon | C14: Undo, duplicate, reset, delete must be easy to spot | D14: Decided (your feedback)
A15: Area hues | B15: Income green #0B7A43 · Debt plum #8E2C8F · Assets teal #0E6670 · Taxes indigo #4338CA · Needs sapphire #1747A6 · Goals rose #B0397A (lighter versions in dark mode) | C15: Sub-tab dots, section titles, charts | D15: Decided (your 'other hues')
A16: Status: Roughly | B16: Solid teal pill, white text | D16: Decided
A17: Status: Guess | B17: Solid purple pill, white text | D17: Decided
A18: Warnings | B18: Solid navy pill, white text. No yellow, orange or red anywhere | D18: Decided
A19: Good | B19: #0B7A43 | C19: Wins, done | D19: Decided
A20: TYPE AND SIZE
A21: Font | B21: Inter (Google Fonts), fallback system sans-serif; IBM Plex Sans and Source Sans 3 tried as options | C21: One font everywhere | D21: Proposed (pick one in the preview)
A22: Sizes | B22: Body 16px weight 500 · labels 14px weight 600 · section titles 18px · page titles 24px · big numbers 32px | C22: Bigger and more solid than the first proposal | D22: Decided (your feedback)
A23: Numbers | B23: Tabular figures so columns of dollars line up | D23: Decided
A24: SHAPE AND SPACE
A25: Corners | B25: 8px on cards and inputs, 6px on buttons, full round on tags | D25: Decided
A26: Spacing | B26: 4px grid: 4, 8, 12, 16, 24, 32 | D26: Decided
A27: Row height | B27: Comfortable 44px (default) or Compact 36px; 34px inputs; every box in a row sits on the same center line | C27: Your 'fields level with one another' | D27: Decided (your feedback)
A28: Chips next to inputs | B28: Sit beside the input on the same line, never above or below it | D28: Decided (your feedback)
A29: Inputs | B29: Filled: 1.5px #8FA2C6 border. Empty: 2px #4E6694 border with a hint like Add APR. Focused: 2px sapphire | C29: Visible borders rule; empty boxes stand out | D29: Decided (v4)
A30: Buttons | B30: Main: filled sapphire, white text. Secondary: white with sapphire border. Icon: 28px square. Max one main button per area | D30: Decided
A31: Row actions | B31: Duplicate, reset, delete as 32px line icons with tooltips, then one 'More ▸' text button. No ⋯ menu | C31: Your 'three dots and caret' note | D31: Decided (your feedback)
A32: Icons | B32: Line icons, 2.25 stroke, 18px, Lucide style (inline SVG or Lucide pinned from unpkg). Never emoji | D32: Decided (v4)
A33: Reference page | B33: spec/SLAM Look Preview.html (version 4) shows every value on this tab in use, light and dark | C33: Match it | D33: Decided (v4)
A34: Current sub-tab | B34: Filled sapphire with white text | D34: Decided
A35: Hover | B35: Lift 1px with a soft shadow; pointer cursor on everything clickable, nothing else | D35: Decided
A36: Screen size | B36: Laptop first: designed at 1440px, must work down to 1280px. Phone layout is phase 6 | D36: Decided
A37: Charts | B37: Apache ECharts from a CDN, using the area hues | C37: One chart library so every chart looks related | D37: Decided
A38: FORMATS
A39: Money | B39: $1,240 in summaries (no cents); $15.99 in entry fields; negative as −$240, never red | D39: Decided
A40: Percent | B40: One decimal: 22.4% | D40: Decided
...

Sheet Words and states
A1: Words, empty states, errors
A2: Situation | B2: What it says | C2: Notes | D2: Status
A3: THE ONE RULE
A4: Every word on screen | B4: Understood in one glance. Short, plain, obvious. If a label needs explaining, change the label | C4: Don't Make Me Think | D4: Decided (Oct 28)
A5: EMPTY STATES (first time a screen is opened)
A6: Home (no client) | B6: 'Start with a new client' + one main button | D6: Proposed
A7: My Money tab, nothing entered | B7: 'Start Fast Track' as the one main button, with 'about 5 minutes' under it | D7: Proposed
A8: A list with no rows | B8: 'No credit cards yet' + '+ Add credit card' | D8: Proposed
A9: A chart missing inputs | B9: Grey outline of the chart + 'Needs rent and take-home' with links to both | D9: Proposed
A10: A metric missing inputs | B10: 'Locked: needs 2 numbers' with links | D10: Decided
A11: Calendar, nothing planned | B11: 'Add your paychecks and bills to see your month' | D11: Proposed
A12: CONFIRMATIONS AND ERRORS
A13: After delete | B13: 'Deleted. Undo' toast, 10 seconds | D13: Decided
A14: Before reset section | B14: 'Clear all 6 debts? You can undo this.' Buttons: 'Clear debts' and 'Keep them' | D14: Proposed
A15: Save failed | B15: 'Not saved yet. Your last change is safe in this tab; export now to be sure.' + Export button | D15: Proposed
A16: Payment too small | B16: 'This payment never pays it off. It needs at least $417 a month.' | D16: Proposed
A17: Backup reminder | B17: 'Last backup 9 days ago.' + 'Back up now' | D17: Proposed
A18: SAMPLE TEXT IN THE MOCKUP
A19: Names and amounts in the Mockup tab | B19: Examples only (Maya R., $1,240, Nov 12). Never hard-code them; real values come from the client's records | D19: Decided

Sheet Navigation
A1: Navigation: where everything lives
A2: Tab or task | B2: Sub-tab or path | C2: What lives here / clicks | D2: Links and notes
A3: THE IDEA
A4: Five tabs, five jobs | B4: Home = this session. My Money = facts about today. Spending = this month. Plan = the future. Report = the report (read only) | D4: If you can't tell which tab something belongs in, ask: is it about now, this month, the future, or a summary?
A5: One home per thing | B5: Every field is entered in exactly one place. Other screens show it as a link back to its home | D5: No more 'Needs in My Money and Spending'
A6: Tabs are places, buttons are actions | B6: Start Fast Track, Start session and One page are modes, so they're buttons or toggles, not tabs
A7: Same spot, every screen | B7: Top bar: left = where am I, middle = 5 tabs, right = 8 tools. Sub-tabs always directly under the main tabs
A8: SITE MAP
A9: Home | B9: Prep | Live | Wrap-up | C9: Session notes, agenda, homework status | D9: Money in one line links to Report, Spending and Plan
A10: My Money | B10: Profile | C10: Why now, gates hub (what applies to me), about you, work and home, accounts, couples split | D10: Gates hub links to every gated section
A11: My Money | B11: Income | C11: Paychecks, benefits, variable income, equity pay | D11: Take-home total feeds Spending and Report
A12: My Money | B12: Debt | C12: Every debt row, credit score, payoff order | D12: Car loan and mortgage also show on Assets (same record)
A13: My Money | B13: Assets | C13: Cash, investments, car, home, other | D13: Net worths show on Report
A14: My Money | B14: Protection | C14: Insurance coverage and gaps | D14: Gaps become to-dos
A15: My Money | B15: Taxes | C15: Filing status, last year, estimates | D15: Rates show on Report
A16: Spending | B16: Budget | C16: Every spending line, the five passes, fixed/variable, who pays, irregular costs | D16: Lines appear on the calendar
A17: Spending | B17: Cash flow calendar | C17: Calendar entries, maybe money, wins, low balance line | D17: Card due dates come from Debt
A18: Spending | B18: Month-end close | C18: Close, misses, carry adjustments | D18: Actuals feed Report > History
A19: Plan | B19: Goals | C19: FI target, assumptions, milestones | D19: FI date shows on Home
A20: Plan | B20: Timeline | C20: FI timeline with sliders and pace bands
A21: Plan | B21: Debt payoff | C21: Payoff chart and extra payment slider | D21: Reads Debt
A22: Plan | B22: Next 12 months | C22: Upcoming events | D22: Each lands on the calendar
A23: Plan | B23: Scenarios | C23: Life event blocks (later)
A24: Report | B24: Overview | C24: Net worth donuts, metrics unlocked, Sankey | D24: Read only; every number links to its home
A25: Report | B25: One-pager | C25: Session summary, send summary
A26: Report | B26: History | C26: Snapshots over time, Wrapped later
A27: ⚙ Coach tools | B27: Lists, Data, Session | C27: Revisit list, homework, snapshots, export/import, reset, private and shared notes, settings, pre-call link | D27: Never shown in client view
A28: + New client | B28: Discovery table | C28: Creates the client from the sales call | D28: Then opens Home in Prep
A29: HOW DO I...? (clicks from anywhere)
A30: Add a credit card | B30: My Money › Debt › + Add debt › Credit card | C30: 3 clicks, or 1 with + Add anything
A31: Say the client got a car | B31: My Money › Profile › gates hub › Car ✓ | C31: 3 clicks; jumps to the new car rows
A32: Log a paycheck that arrived | B32: Spending › Cash flow calendar › chip › Got it | C32: 3 clicks
A33: Mark a bill as partly paid | B33: Spending › Cash flow calendar › chip › Partial | C33: 3 clicks
A34: Link a bill to a card | B34: More ▸ › Paid with › card name | C34: 3 clicks from the bill | D34: Or check several bills and use Link to card in the bulk bar
A35: Close the month | B35: Spending › Month-end close › Review › Close month | C35: 3 clicks
A36: See the FI date | B36: Home (it's on Money in one line) | C36: 0-1 clicks
A37: Find the HSA | B37: 🔍 Find › type 'HSA' | C37: 1 click
A38: Jot something the client said | B38: 📝 | C38: 1 click
A39: Run Fast Track | B39: My Money › Start Fast Track | C39: 2 clicks
A40: Share my screen safely | B40: Client view toggle | C40: 1 click
...

Sheet DMMT check
A1: Don't Make Me Think check
A2: Principle or check | B2: How it's applied | C2: Where | D2: Status | E2: Your comments
A3: TRUNK TEST (Krug: drop someone on any screen; can they answer these?)
A4: What site is this? | B4: 'SLAM' site ID top left on every screen | C4: All screens | D4: Applied
A5: Whose file is this? | B5: Client name next to the site ID | C5: All screens | D5: Applied
A6: What page am I on? | B6: Breadcrumb after the client name, current tab underlined, current sub-tab filled | C6: All screens | D6: Applied
A7: What are the major sections? | B7: Five main tabs, same order everywhere | C7: All screens | D7: Applied
A8: What are my options here? | B8: Sub-tabs right under the tabs; one main (filled blue) button per area | C8: All screens | D8: Applied
A9: How do I search? | B9: 🔍 Find in the same spot on every screen | C9: All screens | D9: Applied
A10: KRUG PRINCIPLES
A11: Obvious what's clickable | B11: Buttons look like buttons, fields have borders, tabs are filled, computed numbers are grey and can't be typed in | C11: Staples | D11: Applied
A12: One main action per area | B12: Each area gets at most one filled blue button (Start session, Next step, End session, + Add). Everything else is outlined or an icon | C12: Home, every section | D12: Fixed today
A13: Don't make them hunt | B13: One home per thing; Find and quick add reach any field in 1 click | C13: Navigation | D13: Fixed today
A14: Omit needless words | B14: Labels are 1-3 words; explanations go in tooltips; copy from the user's side | C14: All copy | D14: Applied
A15: Reduce noise | B15: Status tags only show when a number isn't 'Know it'. Secondary and Tertiary collapsed. Completion is one slim bar on Home | C15: All rows, Home | D15: Fixed today
A16: Conventions over cleverness | B16: Standard patterns: tabs, breadcrumb, undo toast, trash can, caret | C16: Staples | D16: Applied
A17: Mindless choices | B17: Top 4 then Other; defaults filled; 'not sure' fills a guess instead of blocking | C17: Pickers, defaults | D17: Applied
A18: Visual hierarchy | B18: Bigger = more important: #1 next number is a big card, #2 and #3 small. Money in one line has exactly 4 numbers | C18: Home | D18: Fixed today
A19: WHAT WAS FIXED TODAY
A20: Needs lived in two places | B20: My Money had a Needs tab that linked to Spending. Removed; Spending > Budget is Needs' one home | C20: My Money, Spending | D20: Fixed today
A21: Goals lived in two places | B21: Goals were a My Money tab and also on Plan. Moved to Plan > Goals; My Money is only facts about today | C21: My Money, Plan | D21: Fixed today
A22: Fast Track was a tab | B22: It's a mode that walks across tabs, so it's now a 'Start Fast Track' button | C22: My Money | D22: Fixed today
A23: Express form was a separate button | B23: Now a 'By section | One page' toggle on My Money | C23: My Money | D23: Fixed today
A24: Home tried to do everything | B24: Home now has three moments (Prep, Live, Wrap-up) that switch on their own; each shows only what that moment needs and one main button | C24: Home | D24: Fixed today
A25: 'Why are you here' sat on Home | B25: Moved to My Money > Profile > Why now (its one home); the Live agenda's step 1 links to it | C25: Home, Profile | D25: Fixed today
A26: Gates were scattered | B26: Gates hub in Profile; hidden areas show a slim '+ Add [area]' link | C26: Profile | D26: Fixed today
A27: Top bar had 11 loose items | B27: Grouped into left (where am I), middle (5 tabs), right (8 tools) | C27: All screens | D27: Fixed today
A28: WATCH
A29: Two tabs sounded alike | B29: My Money and Report renamed to My Money (enter facts about today) and Report (read the summary) | C29: Main tabs | D29: Fixed today
A30: Paid with was 4 clicks deep | B30: Now 3 clicks via More ▸, or 1 action for many bills via bulk select. The ⋯ menu was removed so there is one way in | C30: Budget | D30: Fixed today
A31: Visuals panel next to forms | B31: Charts beside inputs can crowd the screen; default to Side on wide screens, Below on narrow, Hide is one click | C31: My Money | D31: Watch
A32: Client view | B32: Make sure nothing private leaks into charts or the one-pager | C32: All screens | D32: Watch

Sheet Screens
A1: Screen | B1: Sub-tabs | C1: Purpose | D1: When it's used | E1: Who sees it | F1: Your comments
A2: Home | B2: Prep, Live, Wrap-up (switch on their own) | C2: The session cockpit: where the client is, what we're doing today, the one next thing | D2: Every call | E2: You and client
A3: My Money | B3: Profile, Income, Debt, Assets, Protection, Taxes | C3: Facts about today. Fast Track and One page are modes on top of these tabs | D3: Session 1 and updates | E3: You and client
A4: Spending | B4: Budget, Cash flow calendar, Month-end close | C4: This month: the five passes, the calendar, the close | D4: Session 1 and monthly | E4: You and client
A5: Plan | B5: Goals, Timeline, Debt payoff, Next 12 months, Scenarios | C5: The future: what you're aiming for and what moves it | D5: End of call reveal, check-ins | E5: You and client
A6: Report | B6: Overview, One-pager, History | C6: The report: read-only views of everything above | D6: End of call, monthly | E6: You and client
A7: Discovery (sales call) | C7: Quick table that creates the client and fills the map | D7: Sales call | E7: You only
A8: Pre-call form (client) | C8: Same questions as Profile, tap-only, for the client. Later phase | D8: Before session 1 | E8: Client
A9: Coach tools (⚙) | B9: Lists, Data, Session | C9: Revisit list, homework, snapshots, export, reset, notes, settings | D9: Before and after calls | E9: You only

Sheet Mockup
A1: SLAM screen mockup: each cell is one thing on screen, left to right
A2: How to read it: each item has Primary, Secondary and Tertiary layers. Under each layer, row 1 is what it looks like, row 2 is what kind of thing it is, row 3 is what it does. Move or edit cells freely; put comments in the last column.
A3: Legend | B3: Field: Type a value | C3: Picker: Type a little, pick from a list | D3: Dropdown: Pick one from a short list | E3: Toggle: Two or three choices side by side | F3: Stepper: Minus and plus to set a count | G3: Button: Does something when clicked | H3: Icon button: Small button (duplicate, delete, reset) | I3: Caret: Opens or closes the next layer | J3: Status tag: Know it / Roughly / Not sure / Will email / Not now / Not for me | K3: Computed: App works it out, never typed | L3: Label: Text only, not clickable | M3: Tab: Switches the screen or sub-screen | N3: Chart: Visual | O3: Card: A box holding a few lines or a link
A5: Screen › Section › Item | B5: Layer | C5: Row | D5: 1 | E5: 2 | F5: 3 | G5: 4 | H5: 5 | I5: 6 | J5: 7 | K5: 8 | L5: 9 | M5: 10 | N5: 11 | O5: Your comments
A6: ALL SCREENS
A7: Top bar › Left: where am I | O7: Trunk test: site, client, page and section always visible here
B8: Primary | C8: Looks like | D8: SLAM | E8: Maya R. ▾ | F8: My Money › Debt | G8: Saved ✓
C9: Type | D9: Label | E9: Picker | F9: Label | G9: Computed
C10: What it does | D10: Site ID: Stress Less About Money. Click = Home | E10: Current client; click to switch or '+ New client' | F10: Breadcrumb after the client name; each part clickable | G10: Autosaves every change; 'Unsaved' warning before closing
A12: Top bar › Middle: main tabs | O12: One job per tab. Current tab is underlined and filled
B13: Primary | C13: Looks like | D13: Home | E13: My Money | F13: Spending | G13: Plan | H13: Report
C14: Type | D14: Tab | E14: Tab | F14: Tab | G14: Tab | H14: Tab
C15: What it does | D15: This session: before, during, after | E15: Facts about today | F15: This month: budget, calendar, close | G15: The future: goals, timeline, events | H15: The report: net worth, metrics, one-pager
A17: Top bar › Right: tools | O17: Same 8 tools, same order, every screen
B18: Primary | C18: Looks like | D18: 🔍 Find | E18: + Add anything | F18: 📝 | G18: ↶ | H18: ↷ | I18: $ | Hours | FI days | J18: Client view | K18: ⚙
C19: Type | D19: Field | E19: Field | F19: Icon button | G19: Icon button | H19: Icon button | I19: Toggle | J19: Toggle | K19: Icon button
C20: What it does | D20: Type any field ('HSA') and jump to it | E20: Quick add: 'Netflix 15.99 monthly' | F20: Parking lot: quick note, always one click away | G20: Undo | H20: Redo | I20: Every number converts to time | J20: Screen-share mode: hides coach-only items, bigger text | K20: Coach tools
A22: HOME
A23: Purpose › What Home is for | O23: Home is the session cockpit. Data entry lives in My Money and Spending; reports live in Report
B24: Primary | C24: Looks like | D24: Answers 3 questions in 5 seconds | E24: Changes by moment
C25: Type | D25: Label | E25: Label
C26: What it does | D26: 1. Where is this client now? 2. What are we doing today? 3. What's the one next thing? | E26: Before the call = Prep. During = Live. After = Wrap-up. Switches on its own when you press Start session / End session
A28: Every mode › Client strip
B29: Primary | C29: Looks like | D29: Maya R. | E29: Session 2 of 6 | F29: Next: Nov 12 | G29: Active ▾ | H29: Prep | Live | Wrap-up
C30: Type | D30: Label | E30: Computed | F30: Picker | G30: Dropdown | H30: Tab
C31: What it does | E31: Package tracking | G31: Active, maintenance, paused | H31: Current moment; switches itself, can be clicked
A33: Every mode › Money in one line | O33: Exactly 4 numbers. Everything else is in Report
B34: Primary | C34: Looks like | D34: “You keep $1,240 a month and are on track for FI at 47.” | E34: Net worth | F34: Monthly surplus | G34: Savings rate | H34: FI date
C35: Type | D35: Computed | E35: Computed | F35: Computed | G35: Computed | H35: Computed
C36: What it does | D36: One plain sentence | E36: Click = Report | F36: Click = Spending | G36: Click = Report | H36: Click = Plan
B37: Secondary | C37: Looks like | D37: Since last session ▲
C38: Type | D38: Computed
C39: What it does | D39: Small arrows on each number
A41: Prep (before the call) › Prep
B42: Primary | C42: Looks like | D42: What changed since last time | E42: Open homework: 3 | F42: Due for a check: 4 | G42: Parking lot notes: 2 | H42: Start session
C43: Type | D43: Card | E43: Card | F43: Card | G43: Card | H43: Button
C44: What it does | D44: Net worth, debts paid, new numbers | E44: Click opens the list | F44: Rough or aged numbers | G44: Unfiled notes from last time | H44: The one main button. Switches Home to Live and turns on Guide me
B45: Secondary | C45: Looks like | D45: Edit today's agenda
C46: Type | D46: Button
C47: What it does | D47: Reorder or add steps
...

Sheet Staples
A1: Staple | B1: What it looks like | C1: Where it's used | D1: Your comments
A2: Add button | B2: '+ Add [thing]', outlined, bottom left of every section | C2: Income, Debt, Assets, Needs, Protection, Goals, calendar, events
A3: Add picker | B3: Top 4 big buttons, Other with search, Name your own | C3: Every Add button
A4: Row | B4: Type/name, amount, per, owner, status, ⧉ ↺ 🗑, ▸ More | C4: Every multi-item list
A5: Caret | B5: ▸ More / ▾ Less, opens Secondary then Tertiary | C5: Every row
A6: Status tag | B6: Know it, Roughly, Not sure (Guess), Will email, Not now, Not for me, Computed | C6: Every field and row
A7: Amount box | B7: $ value with 'per' picker (paycheck, week, month, year) | C7: Every money field
A8: Who pays | B8: Me, split, included in rent, covered by someone, N/A, my share | C8: Every Needs line
A9: Paid with | B9: Checking, savings, or a card | C9: Every bill (Tertiary)
A10: Amount: Fixed | Variable | B10: Toggle with a default by category | C10: Every spending line
A11: Timing: Fixed date | Variable date | B11: Toggle with a default by category | C11: Every spending line and calendar entry
A12: Section footer | B12: Total, count, completion bar | C12: Every section
A13: Visuals panel | B13: Chart for this section with a chart picker | C13: Every My Money sub-tab
... A26: Quick add | B26: '+ Add anything' text box in the top bar | C26: All screens

Sheet Rules
A1: SLAM rules: when X, then Y, otherwise Z
A2: Source = Decided (you said it, with when or where) or Proposed (my default; confirm, change or delete). Proposed rows are shaded yellow.
A3: ID | B3: Build status | C3: Rule type | D3: Applies to | E3: When | F3: Then | G3: Otherwise | H3: Example | I3: Source | J3: Your comments | K3: Build phase
A4: R001 | B4: Not started | C4: Gate (show only if) | D4: Accounts gate | E4: An area (cash, investments, real assets, debt) is unchecked | F4: That area's sub-tab, rows, totals and charts don't appear anywhere | G4: Area appears with the rows created by the counts | I4: Decided (Sept: absent, not hidden) | K4: 5
A5: R002 | B5: Not started | C5: Gate (show only if) | D5: Accounts gate | E5: 'None of these' is checked | F5: All four areas count as complete; net worth uses zeros | I5: Decided (Sept 23: every question has an 'I don't') | K5: 5
A6: R003 | B6: Not started | C6: Gate (show only if) | D6: Accounts gate | E6: A type is picked with a count of N | F6: N blank rows of that type are created | I6: Decided (Oct 28: count first, then rows) | K6: 5
A7: R004 | B7: Not started | C7: Gate (show only if) | D7: Work situation | E7: Between jobs, student or retired | F7: Employer match, 401(k) %, paycheck deductions, vesting and equity pay don't appear | G7: They appear for employed or mixed | I7: Decided (Sept: situation gate) | K7: 5
A8: R005 | B8: Not started | C8: Gate (show only if) | D8: Work situation | E8: Self-employed or mixed | F8: Variable income block, tax set-aside %, quarterly estimates and business expenses appear | G8: Hidden | I8: Decided (accepted Oct 28; was proposed) | K8: 5
A9: R006 | B9: Not started | C9: Gate (show only if) | D9: Work situation | E9: Between jobs | F9: Unemployment benefits and runway months appear on Income and Home | G9: Hidden | I9: Decided (accepted Oct 28; was proposed) | K9: 5
A10: R007 | B10: Not started | C10: Gate (show only if) | D10: Household | E10: Solo | F10: No Owner dropdowns, no partner rows, no couples split | G10: Couple: Owner on every row, partner fields, couples split block | I10: Decided (couples support Oct 27) | K10: 5
A11: R008 | B11: Not started | C11: Gate (show only if) | D11: Housing | E11: Rent | F11: Rent line, renters insurance line | G11: Own: mortgage on home asset, property tax, insurance, HOA. Family: housing line defaults to 'covered by someone' | I11: Decided (accepted Oct 28; was proposed) | K11: 5
A12: R009 | B12: Not started | C12: Gate (show only if) | D12: Car gate | E12: Has a car = No | F12: Car insurance, gas, maintenance, registration, tolls, parking, car wash and the car asset don't appear | G12: They appear; transit and Uber appear either way | I12: Decided (your Fields comment) | K12: 5
A13: R010 | B13: Not started | C13: Gate (show only if) | D13: Kids gate | E13: Dependents = 0 | F13: All Kids lines and the kid tax credits don't appear | G13: They appear | I13: Decided (your Fields comment) | K13: 5
A14: R011 | B14: Not started | C14: Gate (show only if) | D14: Pets gate | E14: Pets = 0 | F14: All Pet lines don't appear | G14: They appear | I14: Decided (your Fields comment) | K14: 5
A15: R012 | B15: Not started | C15: Gate (show only if) | D15: Health coverage | E15: Coverage is not confirmed as HSA-eligible | F15: HSA rows (contribution, invested vs cash, HSA account type) don't appear | G15: They appear | I15: Decided (your Mockup comment) | K15: 5
A16: R013 | B16: Not started | C16: Gate (show only if) | D16: Health coverage | E16: Coverage doesn't include an FSA | F16: FSA rows don't appear | G16: They appear | I16: Decided (your Mockup comment) | K16: 5
A17: R014 | B17: Not started | C17: Gate (show only if) | D17: Income | E17: Employer doesn't offer ESPP or RSUs | F17: Equity pay fields don't appear | G17: Appear when ticked in the paycheck row's Secondary: 'Equity pay offered? ☐ ESPP ☐ RSU ☐ Options' (also listed in the gates hub) | I17: Decided (your comment: where would this gate be) | K17: 5
A18: R015 | B18: Not started | C18: Gate (show only if) | D18: Gates hub | E18: Always | F18: Profile has a 'What applies to me' panel listing every gate (car, kids, pets, housing, work, health, equity pay, couple, account types) with its answer. Changing one adds or removes those sections and jumps you there | G18: Each hidden area also shows a slim '+ Add [area]' link in its sub-tab, linked back to the hub | I18: Decided (your comment on R001) | K18: 5
A19: R016 | B19: Not started | C19: Gate (show only if) | D19: Student loan | E19: Private | F19: Repayment plan and PSLF fields don't appear | G19: Federal: they appear | I19: Decided (accepted Oct 28; was proposed) | K19: 5
A20: R017 | B20: Not started | C20: Gate (show only if) | D20: Investment account | E20: Account type picked | F20: Only the fields unique to that type appear (cost basis for brokerage, Roth basis for Roth, invested vs cash for HSA) | I20: Decided (Oct 27: each type carries its own fields) | K20: 5
A21: R018 | B21: Not started | C21: Gate (show only if) | D21: Investment account | E21: Pretax | Roth | Both = Both | F21: Two balance boxes (pretax and Roth) | G21: One balance box | I21: Decided (accepted Oct 28; was proposed) | K21: 5
A22: R019 | B22: Not started | C22: Gate (show only if) | D22: Debt picker | E22: Always | F22: Top 4 shown: credit card, student loan, car loan, personal loan; Other opens the rest with search | I22: Decided (your Mockup comment) | K22: 5
A23: R020 | B23: Not started | C23: Gate (show only if) | D23: Credit card | E23: Payment = Custom | F23: Custom $ box appears | G23: Hidden | I23: Decided (your Mockup comment) | K23: 5
A24: R021 | B24: Not started | C24: Gate (show only if) | D24: Taxes | E24: Income type includes 1099 or self-employed | F24: Quarterly estimates and self-employment tax appear | G24: Hidden | I24: Decided (accepted Oct 28; was proposed) | K24: 5
A25: R022 | B25: Not started | C25: Gate (show only if) | D25: Goals | E25: Milestone = Barista FI | F25: Part-time income field appears | G25: Hidden | I25: Decided (Oct 7 FI definitions) | K25: 5
A26: R023 | B26: Not started | C26: Gate (show only if) | D26: Any sub-tab | E26: Layer = Secondary or Tertiary | F26: Fields stay behind the caret, collapsed by default | G26: Primary always visible | I26: Decided (Oct 28: detail behind carets) | K26: 5
A27: R024 | B27: Not started | C27: Default | D27: Every new row | E27: Row created | F27: All boxes start blank, never 0% or $0; computed results show '–' until inputs exist | H27: ProjectionLab shows '0 years to pay off' on a blank row | I27: Decided (screen review) | K27: 2
A28: R025 | B28: Not started | C28: Default | D28: Goals | E28: No return entered | F28: Return 7%, inflation 2%, withdrawal 4% | I28: Decided (Oct 28: your usual numbers) | K28: 2
A29: R026 | B29: Not started | C29: Default | D29: Goals | E29: Presets | F29: Return (already after inflation): 6% (conservative), 7% (default), 8% (optimistic), 12% (hopeful, no inflation taken out). Inflation: 2% (default), 3%. Withdrawal: 3%, 4% (default), 4.7%, 5.2% | I29: Decided (Oct 28) | K29: 2
A30: R027 | B30: Not started | C30: Default | D30: Coast FI retirement age | E30: Always | F30: Uses the FI target age if set; otherwise 60, editable in Plan > Goals as 'Retire by' | I30: Decided (Oct 28, from Claude Code's question) | K30: 2
A31: R028 | B31: Not started | C31: Default | D31: FI date investing | E31: Always | F31: Monthly surplus counts as invested until an investing split is entered | I31: Decided (Oct 28, from Claude Code's question) | K31: 2
A32: R029 | B32: Not started | C32: Default | D32: Plan | E32: Always | F32: A 'These are big deals' card shows the FI date under each preset side by side, so the client sees how much one assumption moves it | I32: Decided (Oct 28) | K32: 2
A33: R030 | B33: Not started | C33: Default | D33: Goals | E33: No pace picked | F33: Likely (the default presets); Optimistic and Pessimistic use the 8% and 6% presets | I33: Decided (Oct 28, replaces Optimistic default) | K33: 2
A34: R031 | B34: Not started | C34: Default | D34: Goals | E34: No life expectancy | F34: 90 | H34: ProjectionLab uses 85 | I34: Decided (accepted Oct 28; was proposed) | K34: 2
A35: R032 | B35: Not started | C35: Default | D35: Goals | E35: No retirement spending | F35: Equals current spending | I35: Decided (accepted Oct 28; was proposed) | K35: 2
A36: R033 | B36: Not started | C36: Default | D36: Goals | E36: Social Security not set | F36: Full scheduled benefit (likely case), never zero by default | I36: Decided (Oct 2) | K36: 2
A37: R034 | B37: Not started | C37: Default | D37: Engine | E37: Always | F37: Real (today's) dollars; nominal is a toggle | I37: Decided (Oct 2) | K37: 2
A38: R035 | B38: Not started | C38: Default | D38: Split by | E38: Roommates entered | F38: Every shared Needs line defaults to split by roommates + 1 | G38: Client can override per line or just type 'my share' | I38: Decided (your Fields comment) | K38: 2
A39: R036 | B39: Not started | C39: Default | D39: Housing = Family | E39: Housing line | F39: Defaults to 'Covered by someone' with Covered by = Parents | I39: Decided (accepted Oct 28; was proposed) | K39: 2
A40: R037 | B40: Not started | C40: Default | D40: APR = Not sure | E40: Debt row | F40: Fills the typical rate for that debt type from Reference data (Federal Reserve G.19), labeled Guess | H40: Credit card 22.15%, personal loan 11.86%, car 7.14% | I40: Decided (Oct 28; Guess wins over Roughly here) | K40: 2
...

Sheet Rules summary
A1: Rule type | B1: Rules | C1: Proposed (need your OK)
A2: Gate (show only if) | B2: =COUNTIF(Rules!C:C,A2) | C2: =COUNTIFS(Rules!C:C,A2,Rules!I:I,"Proposed*")
A3: Default | B3: =COUNTIF(Rules!C:C,A3) | C3: =COUNTIFS(Rules!C:C,A3,Rules!I:I,"Proposed*")
A4: Entry | B4: =COUNTIF(Rules!C:C,A4) | C4: =COUNTIFS(Rules!C:C,A4,Rules!I:I,"Proposed*")
A5: Status and confidence | B5: =COUNTIF(Rules!C:C,A5) | C5: =COUNTIFS(Rules!C:C,A5,Rules!I:I,"Proposed*")
A6: Completion | B6: =COUNTIF(Rules!C:C,A6) | C6: =COUNTIFS(Rules!C:C,A6,Rules!I:I,"Proposed*")
A7: Order and priority | B7: =COUNTIF(Rules!C:C,A7) | C7: =COUNTIFS(Rules!C:C,A7,Rules!I:I,"Proposed*")
A8: Visibility | B8: =COUNTIF(Rules!C:C,A8) | C8: =COUNTIFS(Rules!C:C,A8,Rules!I:I,"Proposed*")
A9: Data safety | B9: =COUNTIF(Rules!C:C,A9) | C9: =COUNTIFS(Rules!C:C,A9,Rules!I:I,"Proposed*")
A10: Calendar | B10: =COUNTIF(Rules!C:C,A10) | C10: =COUNTIFS(Rules!C:C,A10,Rules!I:I,"Proposed*")
A11: Paid with (bill to card) | B11: =COUNTIF(Rules!C:C,A11) | C11: =COUNTIFS(Rules!C:C,A11,Rules!I:I,"Proposed*")
A12: Staples (same everywhere) | B12: =COUNTIF(Rules!C:C,A12) | C12: =COUNTIFS(Rules!C:C,A12,Rules!I:I,"Proposed*")
A13: Bulk select | B13: =COUNTIF(Rules!C:C,A13) | C13: =COUNTIFS(Rules!C:C,A13,Rules!I:I,"Proposed*")
... A20: Copy and look | B20: =COUNTIF(Rules!C:C,A20) | C20: =COUNTIFS(Rules!C:C,A20,Rules!I:I,"Proposed*")
A21: Total | B21: =SUM(B2:B20) | C21: =SUM(C2:C20)

Sheet Math
A1: Math: every computed number
A2: ID | B2: Name | C2: Formula | D2: Inputs | E2: When something's missing | F2: Notes / example
A3: CONVENTIONS
A4: M00 | B4: Units | C4: All money stored monthly in today's dollars; rates stored as annual decimals (7% = 0.07) | F4: Engine works in real dollars; nominal is a display toggle
A5: M01 | B5: Monthly from any period | C5: weekly × 52/12; every 2 weeks × 26/12; twice a month × 2; yearly / 12; per paycheck uses pay frequency | D5: amount, period | E5: Missing period → treat as monthly and mark Roughly
A6: M02 | B6: Real return | C6: Return presets are already after inflation: 6%, 7%, 8% are real returns. 12% is the hopeful optimistic case with no inflation taken out | D6: return preset | F6: Inflation (2% or 3%) is used only for the nominal display toggle, Social Security and debt in today's dollars
A7: INCOME AND TAXES
A8: M10 | B8: Federal income tax | C8: Taxable = annual gross − pretax deductions − standard deduction (floor 0); apply brackets from Reference data | D8: gross, pretax deductions, filing status, year | E8: No filing status → Single (solo) or Married jointly (couple) | F8: v1 is federal plus FICA only
A9: M11 | B9: FICA | C9: 6.2% Social Security up to the wage base + 1.45% Medicare (+0.9% over $200k single) | D9: gross, year | F9: Self-employed: 15.3% on 92.35% of net earnings, half deductible
A10: M12 | B10: Take-home from gross | C10: gross − federal tax − FICA − pretax deductions (− state when added later) | D10: M10, M11
A11: M13 | B11: Gross from take-home | C11: Solve M12 backwards by bisection to the nearest $1 | D11: take-home, deductions | F11: Marked Computed
A12: M14 | B12: Effective and marginal tax rate | C12: Effective = (federal + FICA) / gross. Marginal = bracket of the last dollar + FICA rate | D12: M10, M11
A13: M15 | B13: Employer match ($/yr) | C13: min(contribution %, match cap %) × match % × gross | D13: 401(k) %, match formula, gross | F13: Unvested part shown separately
A14: M16 | B14: Variable income safe budget | C14: lowest month × (1 − tax set-aside %) | D14: lowest month, set-aside | E14: Missing lowest month → typical month × 0.75, marked Guess
A15: M17 | B15: Real hourly wage | C15: (take-home − work costs) / (paid hours + commute + prep hours), monthly | D15: income, work costs, hours | E15: Missing hours → show 'needs hours' instead of a number
A16: SPENDING
A17: M20 | B17: Line monthly amount | C17: M01 applied to each line; accrual view spreads prepaid and yearly costs across months covered | D17: line amount, period, covers
A18: M21 | B18: My share | C18: If 'my share' typed → use it. Else amount × (1 − covered %) / split by | D18: amount, who pays, covered, split | E18: Split by defaults to roommates + 1
A19: M22 | B19: Support received | C19: Σ (amount − my share) where covered by someone else | D19: M21 across lines | F19: Shown on Report; 'what if it stops' = this added to spending
A20: M23 | B20: Fixed floor | C20: Σ my share of lines with Amount = Fixed | D20: M21 | F20: Feeds runway and Lean FI
A21: M24 | B21: Irregular set-aside | C21: yearly cost / 12 | D21: yearly cost
A22: M25 | B22: Estimate vs actual | C22: difference = actual − estimate; % = difference / estimate | D22: estimate, actual | E22: Estimate 0 → show $ only
A23: M26 | B23: Gut accuracy | C23: Average of |actual − Gut or Rough| / actual across months, per line and overall | D23: history | E23: Fewer than 1 closed month → hidden
A24: M27 | B24: Monthly surplus | C24: take-home − total my-share spending − debt payments not already in spending | D24: M12, M21, debts
A25: M28 | B25: Savings rate (headline) | C25: (surplus + after-tax savings in the budget) / take-home | D25: M27 | F25: Gross version in Show the math: (all saving incl. pretax and match) / gross
A26: M29 | B26: DRAFTT shares | C26: Each letter's total / take-home; Taxes and Therapy optional | D26: lines tagged by letter | F26: Proportions only, no verdict colors
A27: M2A | B27: Housing % | C27: housing my-share / take-home | D27: rent or mortgage, utilities | F27: Reference line at 35%
A28: M2B | B28: Accrual spread and prepaid balance | C28: monthly = amount / months covered; prepaid left = amount − monthly × months elapsed | D28: amount, date paid, months covered
A29: DEBT
A30: M30 | B30: Credit card minimum payment | C30: max($25, 1% of balance + one month's interest), capped at the balance | D30: balance, APR | E30: Statement number overrides | F30: Common issuer formula; confirm
A31: M31 | B31: Payoff months | C31: n = −ln(1 − r·B/P) / ln(1 + r), r = APR/12; round up. 0% → B/P | D31: balance, APR, payment | E31: P ≤ r·B → 'This payment never pays it off' and the payment needed | F31: Sheets: =ROUNDUP(NPER(APR/12, −P, B), 0)
A32: M32 | B32: Total interest | C32: n (unrounded) × P − B | D32: M31 | F32: This formula is the source of truth for one debt. The month-by-month simulation (M34) is only for payoff order with extra payments; it may differ by a few dollars from rounding
A33: M33 | B33: Payday or fee APR | C33: fee / amount borrowed × periods per year | D33: fee, amount, period
A34: M34 | B34: Payoff order with extra payment | C34: Simulate monthly: pay minimums, put extra on the first debt in order; when one clears, roll its payment forward | D34: debts, extra, order | F34: Order: avalanche (APR), snowball (balance), stress (rating, ties by APR)
A35: M35 | B35: Utilization | C35: Σ card balances / Σ limits | D35: cards | E35: No limits → hidden
A36: M36 | B36: Debt-to-income | C36: monthly debt payments / gross monthly income | D36: debts, gross
A37: M37 | B37: Promo solver | C37: Payment needed to clear a 0% balance by the promo end = balance / months left | D37: balance, promo end
A38: ASSETS AND NET WORTH
A39: M40 | B39: Total net worth | C39: Σ assets (vested only) − Σ debts | D39: all accounts
A40: M41 | B40: Liquid net worth | C40: cash + taxable brokerage + Roth contribution basis − consumer debt | D40: accounts, debts | F40: Excludes home, car, retirement growth
...

Sheet Reference data
A1: Reference data: presets, limits, rates, lists
A2: Item | B2: Value | C2: Source | D2: Status
A3: PRESETS (your numbers)
A4: Return (after inflation) | B4: 6% conservative · 7% default · 8% optimistic · 12% hopeful (no inflation taken out) | C4: Your Oct 28 answers | D4: Confirmed by you
A5: Inflation | B5: 2% default · 3% | C5: Your Oct 28 defaults | D5: Confirmed by you
A6: Withdrawal rate | B6: 3% · 4% default · 4.7% · 5.2% | C6: Your Oct 28 defaults | D6: Confirmed by you
A7: 2026 LIMITS
A8: 401(k), 403(b), 457, TSP deferral | B8: $24,500; catch-up 50+ $8,000; ages 60-63 $11,250 | C8: IRS Notice 2025-67, via 401k Specialist | D8: Confirm
A9: IRA (Roth or Traditional) | B9: $7,500; catch-up 50+ $1,100 | C9: IRS Notice 2025-67 | D9: Confirm
A10: Total defined contribution (415c) | B10: $72,000 | C10: IRS Notice 2025-67 | D10: Confirm
A11: HSA | B11: $4,400 self-only · $8,750 family · catch-up 55+ $1,000 | C11: IRS, via HR Morning | D11: Confirm
A12: 2026 TAXES
A13: Standard deduction | B13: Single $16,100 · Married jointly $32,200 | C13: IRS 2026 inflation adjustments, via Journal of Accountancy | D13: Confirm
